<?xml version="1.0"?>
<robot name="quori">

<material name="blue">
    <color rgba="0 0 0.8 1"/>
  </material>
  <material name="black">
    <color rgba="0 0 0 1"/>
  </material>
  <material name="white">
    <color rgba="1 1 1 1"/>
  </material>

  <link name="base_link">
    <visual>
      <origin xyz="0 0 0.1013587" rpy="0 0 0" />
      <geometry>
        <cylinder length="0.2027174" radius="0.2413"/>
      </geometry>
      <material name="black"/>
    </visual>
  </link>

   <link name="lower_torso">
    <visual>
      <origin rpy="0 0 -1.57079632679" xyz="0.02 0 -0.2007174"/>
      <geometry>
        <mesh filename="package://quori_description/meshes/180915_Lower Torso.dae"/>
      </geometry>
    </visual>
  </link>

  <joint name="turret_joint" type="revolute">
    <origin xyz="0 0 0.2027174" rpy="0 0 0"/>
    <parent link="base_link"/>
    <child link="lower_torso"/>
    <axis xyz="0 0 1" />
    <limit lower="-3.14" upper="3.14" effort="1" velocity="3"/>
  </joint>

   <link name="upper_torso">
    <visual>
      <origin rpy="0 0 -1.57079632679" xyz="0.02 0 -0.5476974"/>
      <geometry>
        <mesh filename="package://quori_description/meshes/0917_Upper Torso+Waist.dae"/>
      </geometry>
    </visual>
  </link>

   <joint name="waist_hinge" type="revolute">
    <origin xyz="0 0 0.34798" rpy="0 0 0"/>
    <parent link="lower_torso"/>
    <child link="upper_torso"/>
    <axis xyz="0 1 0" />
    <limit lower="-0.26" upper="0.52" effort="1" velocity="3"/>
  </joint>

  <link name="right_arm_base">
  </link>

  <joint name="right_arm_r1" type="revolute">
    <origin xyz="0.015 -0.16403066 0.43021758" rpy="0 0 0"/>
    <parent link="upper_torso"/>
    <child link="right_arm_base"/>
    <axis xyz="0 1 0" />
    <limit lower="-3.14" upper="3.14" effort="1" velocity="3"/>
  </joint>

  <link name="right_arm_upper">
    <visual>
      <origin rpy="-1.57079632679 0 0" xyz="0.165 -0.9765 -0.137"/>
      <geometry>
        <mesh filename="package://quori_description/meshes/0917_Upper Arm+gear_right.dae"/>
      </geometry>
    </visual>
  </link>

  <joint name="right_arm_r2" type="revolute">
    <origin xyz="0 0 0" rpy="0 0 0"/>
    <parent link="right_arm_base"/>
    <child link="right_arm_upper"/>
    <axis xyz="0 0 1" />
    <limit lower="-1.1" upper="1.1" effort="1" velocity="3"/>
  </joint>

  <link name="right_arm_upper2lower">
    <visual>
    <origin rpy="-1.57079632679 0 0" xyz="0 -0.13 0"/>
      <geometry>
        <cylinder length="0.08" radius="0.015"/>
      </geometry>
      <material name="white"/>
    </visual>
  </link>

  <joint name="right_arm_upper2lower_j" type="fixed">
    <parent link="right_arm_upper"/>
    <child link="right_arm_upper2lower"/>
  </joint>

  <link name="right_arm_lower">
    <visual>
      <origin rpy="-1.57079632679 0 0.25" xyz="0.416 -0.73 -0.0005" />
      <geometry>
        <mesh filename="package://quori_description/meshes/0917_Lower Arm_right.dae" />
      </geometry>
    </visual>
  </link>

  <joint name="right_arm_lower_r1" type="revolute">
    <origin xyz="0 -0.15 0" rpy="0 0 0"/>
    <parent link="right_arm_upper"/>
    <child link="right_arm_lower"/>
    <axis xyz="0 1 0" />
    <limit lower="-3.14" upper="3.14" effort="1" velocity="3"/>
  </joint>


  <link name="left_arm_base">
  </link>

  <joint name="left_arm_r1" type="revolute">
    <origin xyz="0.015 0.16403066 0.43021758" rpy="0 0 0"/>
    <parent link="upper_torso"/>
    <child link="left_arm_base"/>
    <axis xyz="0 1 0" />
    <limit lower="-3.14" upper="3.14" effort="1" velocity="3"/>
  </joint>

  <link name="left_arm_upper">
    <visual>
      <origin rpy="-1.57079632679 0 -3.14" xyz="0.165 0.9765 -0.137"/>
      <geometry>
        <mesh filename="package://quori_description/meshes/0917_Upper Arm+gear_left.dae"/>
      </geometry>
    </visual>
  </link>

  <joint name="left_arm_r2" type="revolute">
    <origin xyz="0 0 0" rpy="0 0 0"/>
    <parent link="left_arm_base"/>
    <child link="left_arm_upper"/>
    <axis xyz="0 0 1" />
    <limit lower="-1.1" upper="1.1" effort="1" velocity="3"/>
  </joint>

  <link name="left_arm_upper2lower">
    <visual>
    <origin rpy="-1.57079632679 0 0" xyz="0 0.13 0"/>
      <geometry>
        <cylinder length="0.08" radius="0.015"/>
      </geometry>
      <material name="white"/>
    </visual>
  </link>

  <joint name="left_arm_upper2lower_j" type="fixed">
    <parent link="left_arm_upper"/>
    <child link="left_arm_upper2lower"/>
  </joint>

  <link name="left_arm_lower">
    <visual>
      <origin rpy="1.57079632679 3.1416 -0.25" xyz="0.416 0.73 0.0005"/>
      <geometry>
        <mesh filename="package://quori_description/meshes/0917_Lower_Arm_left.dae" />
      </geometry>
    </visual>
  </link>

  <joint name="left_arm_lower_r1" type="revolute">
    <origin xyz="0 0.15 0" rpy="0 0 0"/>
    <parent link="left_arm_upper"/>
    <child link="left_arm_lower"/>
    <axis xyz="0 1 0" />
    <limit lower="-1.1" upper="1.1" effort="1" velocity="3"/>
  </joint>

  <link name="head">
    <visual>
      <origin rpy="0 0 -1.57079632679" xyz="0.01 0 -1.11" />
      <geometry>
        <mesh filename="package://quori_description/meshes/0917_Helmet_Duripod.dae" />
      </geometry>
    </visual>
  </link>

  <joint name="head_joint" type="fixed">
    <origin xyz="0 0 0.554" rpy="0 0 0" />
    <parent link="upper_torso" />
    <child link="head" />
  </joint>


  <link name="head_camera">
    <visual>
      <geometry>
        <box size="0.04 0.11 0.04"/>
      </geometry>
      <origin rpy="0 0 0" xyz="0 0 -0"/>
      <material name="black"/>
    </visual>
  </link>

  <joint name="head_Camera_joint" type="fixed">
    <origin xyz="0.055 0 0.21" rpy="0 0 0" />
    <parent link="head" />
    <child link="head_camera" />
  </joint>

   <link name="head_mic">
    <visual>
      <geometry>
        <cylinder length="0.002" radius="0.03"/>
      </geometry>
      <origin rpy="0 0 0" xyz="0 0 -0"/>
      <material name="blue"/>
    </visual>
  </link>

  <joint name="head_Mic_joint" type="fixed">
    <origin xyz="-0.008 0 0.218" rpy="0 -.3 0" />
    <parent link="head" />
    <child link="head_mic" />
</joint>

</robot>
